Workbook

Sheet P-T dataset
A1: Ref | B1: Doi | C1: Sample | D1: P (GPa) | E1: T (°C) | F1: Type | G1: Label | H1: SiO2 | I1: TiO2 | J1: Al2O3 | K1: Cr2O3 | L1: FeO | M1: MnO | N1: MgO | O1: CaO | P1: Na2O | Q1: K2O | R1: Total | S1: Oxygen | T1: Coefficient | U1: Si | V1: Ti | W1: Al | X1: Cr | Y1: Fe | Z1: Mn | AA1: Mg | AB1: Ca | AC1: Na | AD1: K | AE1: Total | AF1: Fe3+ Droop | AG1: Fe3+/Fetot Droop | AH1: Fe2+ | AI1: Si+Ti | AJ1: Ca+Mg+Fe+Mn（all Fe as Fe2+）
A2: Akaogi and Akimoto (1979) | B2: 10.1016/0031-9201(79)90088-8 | C2: S-18 | D2: 4.5 | E2: 1200 | F2: Peridotite | G2: Peridotitic | H2: 41.54 | I2: 0.4 | J2: 22.27 | K2: 0.75 | L2: 8.95 | N2: 18.3 | O2: 6.75 | R2: =SUM(H2:Q2) -> 98.96 | S2: 12 | T2: =S2/(H2*'Molecular Weight'!$C$2/'Molecular Weight'!$D$2+I2*'Molecular Weight'!$C$3/'Molecular Weight'!$D$3+J2*'Molecular Weight'!$C$4/'Molecular Weight'!$D$4+K2*'Molecular Weight'!$C$5/'Molecular Weight'!$D$5+L2*'Molecular Weight'!$C$6/'Molecular Weight'!$D$6+M2*'Molecular Weight'!$C$8/'Molecular Weight'!$D$8+N2*'Molecular Weight'!$C$9/'Molecular Weight'!$D$9+O2*'Molecular Weight'!$C$10/'Molecular Weight'!$D$10+P2*'Molecular Weight'!$C$11/'Molecular Weight'!$D$11+Q2*'Molecular Weight'!$C$12/'Molecular Weight'!$D$12) -> 4.3447777 | U2: =H2*T2*'Molecular Weight'!$B$2/'Molecular Weight'!$D$2 -> 3.0040291 | V2: =I2*T2*'Molecular Weight'!$B$3/'Molecular Weight'!$D$3 -> 0.021751078 | W2: =T2*J2*'Molecular Weight'!$B$4/'Molecular Weight'!$D$4 -> 1.8979639 | X2: =K2*T2*'Molecular Weight'!$B$5/'Molecular Weight'!$D$5 -> 0.042878917 | Y2: =L2*T2*'Molecular Weight'!$B$6/'Molecular Weight'!$D$6 -> 0.54128286 | Z2: =M2*T2*'Molecular Weight'!$B$8/'Molecular Weight'!$D$8 -> 0 | AA2: =N2*T2*'Molecular Weight'!$B$9/'Molecular Weight'!$D$9 -> 1.9729388 | AB2: =O2*T2*'Molecular Weight'!$B$10/'Molecular Weight'!$D$10 -> 0.52295381 | AC2: =P2*T2*'Molecular Weight'!$B$11/'Molecular Weight'!$D$11 -> 0 | AD2: =Q2*T2*'Molecular Weight'!$B$12/'Molecular Weight'!$D$12 -> 0 | AE2: =SUM(U2:AD2) -> 8.0037984 | AF2: =IF(IF(2*12*(1-8/AE2)<0,0,2*12*(1-8/AE2))<Y2,IF(2*12*(1-8/AE2)<0,0,2*12*(1-8/AE2)),Y2) -> 0.011389879 | AG2: =AF2/Y2 -> 0.02104238 | AH2: =Y2-AF2 -> 0.52989298 | AI2: =SUM(U2,V2) -> 3.0257802 | AJ2: =SUM(AA2,AB2,Z2,Y2) -> 3.0371754
A3: Akaogi and Akimoto (1979) | B3: 10.1016/0031-9201(79)90088-8 | C3: N-6 | D3: 4.5 | E3: 1200 | F3: Peridotite | G3: Peridotitic | H3: 40.89 | I3: 0.41 | J3: 22 | K3: 0.79 | L3: 10.98 | N3: 17.11 | O3: 6.28 | R3: =SUM(H3:Q3) -> 98.46 | S3: 12 | T3: =S3/(H3*'Molecular Weight'!$C$2/'Molecular Weight'!$D$2+I3*'Molecular Weight'!$C$3/'Molecular Weight'!$D$3+J3*'Molecular Weight'!$C$4/'Molecular Weight'!$D$4+K3*'Molecular Weight'!$C$5/'Molecular Weight'!$D$5+L3*'Molecular Weight'!$C$6/'Molecular Weight'!$D$6+M3*'Molecular Weight'!$C$8/'Molecular Weight'!$D$8+N3*'Molecular Weight'!$C$9/'Molecular Weight'!$D$9+O3*'Molecular Weight'!$C$10/'Molecular Weight'!$D$10+P3*'Molecular Weight'!$C$11/'Molecular Weight'!$D$11+Q3*'Molecular Weight'!$C$12/'Molecular Weight'!$D$12) -> 4.4057036 | U3: =H3*T3*'Molecular Weight'!$B$2/'Molecular Weight'!$D$2 -> 2.998489 | V3: =I3*T3*'Molecular Weight'!$B$3/'Molecular Weight'!$D$3 -> 0.02260749 | W3: =T3*J3*'Molecular Weight'!$B$4/'Molecular Weight'!$D$4 -> 1.9012452 | X3: =K3*T3*'Molecular Weight'!$B$5/'Molecular Weight'!$D$5 -> 0.045799143 | Y3: =L3*T3*'Molecular Weight'!$B$6/'Molecular Weight'!$D$6 -> 0.67336617 | Z3: =M3*T3*'Molecular Weight'!$B$8/'Molecular Weight'!$D$8 -> 0 | AA3: =N3*T3*'Molecular Weight'!$B$9/'Molecular Weight'!$D$9 -> 1.8705109 | AB3: =O3*T3*'Molecular Weight'!$B$10/'Molecular Weight'!$D$10 -> 0.49336339 | AC3: =P3*T3*'Molecular Weight'!$B$11/'Molecular Weight'!$D$11 -> 0 | AD3: =Q3*T3*'Molecular Weight'!$B$12/'Molecular Weight'!$D$12 -> 0 | AE3: =SUM(U3:AD3) -> 8.0053813 | AF3: =IF(IF(2*12*(1-8/AE3)<0,0,2*12*(1-8/AE3))<Y3,IF(2*12*(1-8/AE3)<0,0,2*12*(1-8/AE3)),Y3) -> 0.016133076 | AG3: =AF3/Y3 -> 0.023958845 | AH3: =Y3-AF3 -> 0.6572331 | AI3: =SUM(U3,V3) -> 3.0210965 | AJ3: =SUM(AA3,AB3,Z3,Y3) -> 3.0372405
A4: Akaogi and Akimoto (1979) | B4: 10.1016/0031-9201(79)90088-8 | C4: S-9 | D4: 7.5 | E4: 1200 | F4: Peridotite | G4: Peridotitic | H4: 42.03 | I4: 0.65 | J4: 20.58 | K4: 1.1 | L4: 10.42 | N4: 18.33 | O4: 5.95 | R4: =SUM(H4:Q4) -> 99.06 | S4: 12 | T4: =S4/(H4*'Molecular Weight'!$C$2/'Molecular Weight'!$D$2+I4*'Molecular Weight'!$C$3/'Molecular Weight'!$D$3+J4*'Molecular Weight'!$C$4/'Molecular Weight'!$D$4+K4*'Molecular Weight'!$C$5/'Molecular Weight'!$D$5+L4*'Molecular Weight'!$C$6/'Molecular Weight'!$D$6+M4*'Molecular Weight'!$C$8/'Molecular Weight'!$D$8+N4*'Molecular Weight'!$C$9/'Molecular Weight'!$D$9+O4*'Molecular Weight'!$C$10/'Molecular Weight'!$D$10+P4*'Molecular Weight'!$C$11/'Molecular Weight'!$D$11+Q4*'Molecular Weight'!$C$12/'Molecular Weight'!$D$12) -> 4.3658113 | U4: =H4*T4*'Molecular Weight'!$B$2/'Molecular Weight'!$D$2 -> 3.0541785 | V4: =I4*T4*'Molecular Weight'!$B$3/'Molecular Weight'!$D$3 -> 0.035516612 | W4: =T4*J4*'Molecular Weight'!$B$4/'Molecular Weight'!$D$4 -> 1.7624244 | X4: =K4*T4*'Molecular Weight'!$B$5/'Molecular Weight'!$D$5 -> 0.063193531 | Y4: =L4*T4*'Molecular Weight'!$B$6/'Molecular Weight'!$D$6 -> 0.6332371 | Z4: =M4*T4*'Molecular Weight'!$B$8/'Molecular Weight'!$D$8 -> 0 | AA4: =N4*T4*'Molecular Weight'!$B$9/'Molecular Weight'!$D$9 -> 1.98574 | AB4: =O4*T4*'Molecular Weight'!$B$10/'Molecular Weight'!$D$10 -> 0.46320572 | AC4: =P4*T4*'Molecular Weight'!$B$11/'Molecular Weight'!$D$11 -> 0 | AD4: =Q4*T4*'Molecular Weight'!$B$12/'Molecular Weight'!$D$12 -> 0 | AE4: =SUM(U4:AD4) -> 7.9974959 | AF4: =IF(IF(2*12*(1-8/AE4)<0,0,2*12*(1-8/AE4))<Y4,IF(2*12*(1-8/AE4)<0,0,2*12*(1-8/AE4)),Y4) -> 0 | AG4: =AF4/Y4 -> 0 | AH4: =Y4-AF4 -> 0.6332371 | AI4: =SUM(U4,V4) -> 3.0896952 | AJ4: =SUM(AA4,AB4,Z4,Y4) -> 3.0821828
A5: Akaogi and Akimoto (1979) | B5: 10.1016/0031-9201(79)90088-8 | C5: N-2 | D5: 7.5 | E5: 1200 | F5: Peridotite | G5: Peridotitic | H5: 42.01 | I5: 0.56 | J5: 21.46 | K5: 1.16 | L5: 11.13 | N5: 16.98 | O5: 6.35 | R5: =SUM(H5:Q5) -> 99.65 | S5: 12 | T5: =S5/(H5*'Molecular Weight'!$C$2/'Molecular Weight'!$D$2+I5*'Molecular Weight'!$C$3/'Molecular Weight'!$D$3+J5*'Molecular Weight'!$C$4/'Molecular Weight'!$D$4+K5*'Molecular Weight'!$C$5/'Molecular Weight'!$D$5+L5*'Molecular Weight'!$C$6/'Molecular Weight'!$D$6+M5*'Molecular Weight'!$C$8/'Molecular Weight'!$D$8+N5*'Molecular Weight'!$C$9/'Molecular Weight'!$D$9+O5*'Molecular Weight'!$C$10/'Molecular Weight'!$D$10+P5*'Molecular Weight'!$C$11/'Molecular Weight'!$D$11+Q5*'Molecular Weight'!$C$12/'Molecular Weight'!$D$12) -> 4.3536543 | U5: =H5*T5*'Molecular Weight'!$B$2/'Molecular Weight'!$D$2 -> 3.0442246 | V5: =I5*T5*'Molecular Weight'!$B$3/'Molecular Weight'!$D$3 -> 0.030513722 | W5: =T5*J5*'Molecular Weight'!$B$4/'Molecular Weight'!$D$4 -> 1.8326681 | X5: =K5*T5*'Molecular Weight'!$B$5/'Molecular Weight'!$D$5 -> 0.066454884 | Y5: =L5*T5*'Molecular Weight'!$B$6/'Molecular Weight'!$D$6 -> 0.67450128 | Z5: =M5*T5*'Molecular Weight'!$B$8/'Molecular Weight'!$D$8 -> 0 | AA5: =N5*T5*'Molecular Weight'!$B$9/'Molecular Weight'!$D$9 -> 1.8343685 | AB5: =O5*T5*'Molecular Weight'!$B$10/'Molecular Weight'!$D$10 -> 0.49296905 | AC5: =P5*T5*'Molecular Weight'!$B$11/'Molecular Weight'!$D$11 -> 0 | AD5: =Q5*T5*'Molecular Weight'!$B$12/'Molecular Weight'!$D$12 -> 0 | AE5: =SUM(U5:AD5) -> 7.9757002 | AF5: =IF(IF(2*12*(1-8/AE5)<0,0,2*12*(1-8/AE5))<Y5,IF(2*12*(1-8/AE5)<0,0,2*12*(1-8/AE5)),Y5) -> 0 | AG5: =AF5/Y5 -> 0 | AH5: =Y5-AF5 -> 0.67450128 | AI5: =SUM(U5,V5) -> 3.0747383 | AJ5: =SUM(AA5,AB5,Z5,Y5) -> 3.0018388
A6: Akaogi and Akimoto (1979) | B6: 10.1016/0031-9201(79)90088-8 | C6: S-15 | D6: 14.4 | E6: 1200 | F6: Peridotite | G6: Peridotitic | H6: 46.26 | I6: 0.37 | J6: 16.03 | K6: 0.52 | L6: 5.07 | N6: 24.76 | O6: 4.89 | R6: =SUM(H6:Q6) -> 97.9 | S6: 12 | T6: =S6/(H6*'Molecular Weight'!$C$2/'Molecular Weight'!$D$2+I6*'Molecular Weight'!$C$3/'Molecular Weight'!$D$3+J6*'Molecular Weight'!$C$4/'Molecular Weight'!$D$4+K6*'Molecular Weight'!$C$5/'Molecular Weight'!$D$5+L6*'Molecular Weight'!$C$6/'Molecular Weight'!$D$6+M6*'Molecular Weight'!$C$8/'Molecular Weight'!$D$8+N6*'Molecular Weight'!$C$9/'Molecular Weight'!$D$9+O6*'Molecular Weight'!$C$10/'Molecular Weight'!$D$10+P6*'Molecular Weight'!$C$11/'Molecular Weight'!$D$11+Q6*'Molecular Weight'!$C$12/'Molecular Weight'!$D$12) -> 4.2806843 | U6: =H6*T6*'Molecular Weight'!$B$2/'Molecular Weight'!$D$2 -> 3.2960129 | V6: =I6*T6*'Molecular Weight'!$B$3/'Molecular Weight'!$D$3 -> 0.019822944 | W6: =T6*J6*'Molecular Weight'!$B$4/'Molecular Weight'!$D$4 -> 1.3460057 | X6: =K6*T6*'Molecular Weight'!$B$5/'Molecular Weight'!$D$5 -> 0.02929082 | Y6: =L6*T6*'Molecular Weight'!$B$6/'Molecular Weight'!$D$6 -> 0.30210286 | Z6: =M6*T6*'Molecular Weight'!$B$8/'Molecular Weight'!$D$8 -> 0 | AA6: =N6*T6*'Molecular Weight'!$B$9/'Molecular Weight'!$D$9 -> 2.6300184 | AB6: =O6*T6*'Molecular Weight'!$B$10/'Molecular Weight'!$D$10 -> 0.37326224 | AC6: =P6*T6*'Molecular Weight'!$B$11/'Molecular Weight'!$D$11 -> 0 | AD6: =Q6*T6*'Molecular Weight'!$B$12/'Molecular Weight'!$D$12 -> 0 | AE6: =SUM(U6:AD6) -> 7.9965159 | AF6: =IF(IF(2*12*(1-8/AE6)<0,0,2*12*(1-8/AE6))<Y6,IF(2*12*(1-8/AE6)<0,0,2*12*(1-8/AE6)),Y6) -> 0 | AG6: =AF6/Y6 -> 0 | AH6: =Y6-AF6 -> 0.30210286 | AI6: =SUM(U6,V6) -> 3.3158359 | AJ6: =SUM(AA6,AB6,Z6,Y6) -> 3.3053835
A7: Akaogi and Akimoto (1979) | B7: 10.1016/0031-9201(79)90088-8 | C7: S-6 | D7: 14.6 | E7: 1200 | F7: Peridotite | G7: Peridotitic | H7: 46.11 | I7: 0.46 | J7: 15.64 | K7: 0.24 | L7: 8.04 | N7: 20.88 | O7: 8.16 | R7: =SUM(H7:Q7) -> 99.53 | S7: 12 | T7: =S7/(H7*'Molecular Weight'!$C$2/'Molecular Weight'!$D$2+I7*'Molecular Weight'!$C$3/'Molecular Weight'!$D$3+J7*'Molecular Weight'!$C$4/'Molecular Weight'!$D$4+K7*'Molecular Weight'!$C$5/'Molecular Weight'!$D$5+L7*'Molecular Weight'!$C$6/'Molecular Weight'!$D$6+M7*'Molecular Weight'!$C$8/'Molecular Weight'!$D$8+N7*'Molecular Weight'!$C$9/'Molecular Weight'!$D$9+O7*'Molecular Weight'!$C$10/'Molecular Weight'!$D$10+P7*'Molecular Weight'!$C$11/'Molecular Weight'!$D$11+Q7*'Molecular Weight'!$C$12/'Molecular Weight'!$D$12) -> 4.3058266 | U7: =H7*T7*'Molecular Weight'!$B$2/'Molecular Weight'!$D$2 -> 3.3046216 | V7: =I7*T7*'Molecular Weight'!$B$3/'Molecular Weight'!$D$3 -> 0.02478949 | W7: =T7*J7*'Molecular Weight'!$B$4/'Molecular Weight'!$D$4 -> 1.3209715 | X7: =K7*T7*'Molecular Weight'!$B$5/'Molecular Weight'!$D$5 -> 0.013598242 | Y7: =L7*T7*'Molecular Weight'!$B$6/'Molecular Weight'!$D$6 -> 0.48188817 | Z7: =M7*T7*'Molecular Weight'!$B$8/'Molecular Weight'!$D$8 -> 0 | AA7: =N7*T7*'Molecular Weight'!$B$9/'Molecular Weight'!$D$9 -> 2.2309097 | AB7: =O7*T7*'Molecular Weight'!$B$10/'Molecular Weight'!$D$10 -> 0.62652541 | AC7: =P7*T7*'Molecular Weight'!$B$11/'Molecular Weight'!$D$11 -> 0 | AD7: =Q7*T7*'Molecular Weight'!$B$12/'Molecular Weight'!$D$12 -> 0 | AE7: =SUM(U7:AD7) -> 8.0033041 | AF7: =IF(IF(2*12*(1-8/AE7)<0,0,2*12*(1-8/AE7))<Y7,IF(2*12*(1-8/AE7)<0,0,2*12*(1-8/AE7)),Y7) -> 0.0099080782 | AG7: =AF7/Y7 -> 0.020560949 | AH7: =Y7-AF7 -> 0.47198009 | AI7: =SUM(U7,V7) -> 3.3294111 | AJ7: =SUM(AA7,AB7,Z7,Y7) -> 3.3393232
A8: Auzanneau 2009 | B8: 10.1007/s00410-009-0412-7 | C8: PC3-2001-13 | D8: 1.9 | E8: 800 | F8: Metagreywacke | G8: Basaltic | H8: 38.31 | I8: 0.47 | J8: 21.24 | L8: 28.43 | M8: 0.87 | N8: 5.45 | O8: 5.08 | P8: 0.13 | Q8: 0.02 | R8: =SUM(H8:Q8) -> 100 | S8: 12 | T8: =S8/(H8*'Molecular Weight'!$C$2/'Molecular Weight'!$D$2+I8*'Molecular Weight'!$C$3/'Molecular Weight'!$D$3+J8*'Molecular Weight'!$C$4/'Molecular Weight'!$D$4+K8*'Molecular Weight'!$C$5/'Molecular Weight'!$D$5+L8*'Molecular Weight'!$C$6/'Molecular Weight'!$D$6+M8*'Molecular Weight'!$C$8/'Molecular Weight'!$D$8+N8*'Molecular Weight'!$C$9/'Molecular Weight'!$D$9+O8*'Molecular Weight'!$C$10/'Molecular Weight'!$D$10+P8*'Molecular Weight'!$C$11/'Molecular Weight'!$D$11+Q8*'Molecular Weight'!$C$12/'Molecular Weight'!$D$12) -> 4.7092988 | U8: =H8*T8*'Molecular Weight'!$B$2/'Molecular Weight'!$D$2 -> 3.0028834 | V8: =I8*T8*'Molecular Weight'!$B$3/'Molecular Weight'!$D$3 -> 0.027701758 | W8: =T8*J8*'Molecular Weight'!$B$4/'Molecular Weight'!$D$4 -> 1.9620539 | X8: =K8*T8*'Molecular Weight'!$B$5/'Molecular Weight'!$D$5 -> 0 | Y8: =L8*T8*'Molecular Weight'!$B$6/'Molecular Weight'!$D$6 -> 1.8636604 | Z8: =M8*T8*'Molecular Weight'!$B$8/'Molecular Weight'!$D$8 -> 0.057754299 | AA8: =N8*T8*'Molecular Weight'!$B$9/'Molecular Weight'!$D$9 -> 0.63686547 | AB8: =O8*T8*'Molecular Weight'!$B$10/'Molecular Weight'!$D$10 -> 0.42659126 | AC8: =P8*T8*'Molecular Weight'!$B$11/'Molecular Weight'!$D$11 -> 0.019755045 | AD8: =Q8*T8*'Molecular Weight'!$B$12/'Molecular Weight'!$D$12 -> 0.0019997022 | AE8: =SUM(U8:AD8) -> 7.9992653 | AF8: =IF(IF(2*12*(1-8/AE8)<0,0,2*12*(1-8/AE8))<Y8,IF(2*12*(1-8/AE8)<0,0,2*12*(1-8/AE8)),Y8) -> 0 | AG8: =AF8/Y8 -> 0 | AH8: =Y8-AF8 -> 1.8636604 | AI8: =SUM(U8,V8) -> 3.0305852 | AJ8: =SUM(AA8,AB8,Z8,Y8) -> 2.9848714
A9: Auzanneau 2009 | B9: 10.1007/s00410-009-0412-7 | C9: PC3-2001-12 | D9: 2.1 | E9: 800 | F9: Metagreywacke | G9: Basaltic | H9: 38.49 | I9: 0.52 | J9: 21.29 | L9: 26.87 | M9: 0.55 | N9: 5.35 | O9: 6.81 | P9: 0.12 | Q9: 0.01 | R9: =SUM(H9:Q9) -> 100.01 | S9: 12 | T9: =S9/(H9*'Molecular Weight'!$C$2/'Molecular Weight'!$D$2+I9*'Molecular Weight'!$C$3/'Molecular Weight'!$D$3+J9*'Molecular Weight'!$C$4/'Molecular Weight'!$D$4+K9*'Molecular Weight'!$C$5/'Molecular Weight'!$D$5+L9*'Molecular Weight'!$C$6/'Molecular Weight'!$D$6+M9*'Molecular Weight'!$C$8/'Molecular Weight'!$D$8+N9*'Molecular Weight'!$C$9/'Molecular Weight'!$D$9+O9*'Molecular Weight'!$C$10/'Molecular Weight'!$D$10+P9*'Molecular Weight'!$C$11/'Molecular Weight'!$D$11+Q9*'Molecular Weight'!$C$12/'Molecular Weight'!$D$12) -> 4.6898102 | U9: =H9*T9*'Molecular Weight'!$B$2/'Molecular Weight'!$D$2 -> 3.0045073 | V9: =I9*T9*'Molecular Weight'!$B$3/'Molecular Weight'!$D$3 -> 0.030521919 | W9: =T9*J9*'Molecular Weight'!$B$4/'Molecular Weight'!$D$4 -> 1.9585339 | X9: =K9*T9*'Molecular Weight'!$B$5/'Molecular Weight'!$D$5 -> 0 | Y9: =L9*T9*'Molecular Weight'!$B$6/'Molecular Weight'!$D$6 -> 1.7541091 | Z9: =M9*T9*'Molecular Weight'!$B$8/'Molecular Weight'!$D$8 -> 0.036360243 | AA9: =N9*T9*'Molecular Weight'!$B$9/'Molecular Weight'!$D$9 -> 0.62259267 | AB9: =O9*T9*'Molecular Weight'!$B$10/'Molecular Weight'!$D$10 -> 0.56950085 | AC9: =P9*T9*'Molecular Weight'!$B$11/'Molecular Weight'!$D$11 -> 0.018159962 | AD9: =Q9*T9*'Molecular Weight'!$B$12/'Molecular Weight'!$D$12 -> 0.00099571343 | AE9: =SUM(U9:AD9) -> 7.9952817 | AF9: =IF(IF(2*12*(1-8/AE9)<0,0,2*12*(1-8/AE9))<Y9,IF(2*12*(1-8/AE9)<0,0,2*12*(1-8/AE9)),Y9) -> 0 | AG9: =AF9/Y9 -> 0 | AH9: =Y9-AF9 -> 1.7541091 | AI9: =SUM(U9,V9) -> 3.0350292 | AJ9: =SUM(AA9,AB9,Z9,Y9) -> 2.9825629
A10: Auzanneau 2009 | B10: 10.1007/s00410-009-0412-7 | C10: PC3-2000-13B | D10: 2.3 | E10: 850 | F10: Metagreywacke | G10: Basaltic | H10: 38 | I10: 0.88 | J10: 21.42 | L10: 25.72 | M10: 0.8 | N10: 5.96 | O10: 7.02 | P10: 0.15 | Q10: 0.07 | R10: =SUM(H10:Q10) -> 100.02 | S10: 12 | T10: =S10/(H10*'Molecular Weight'!$C$2/'Molecular Weight'!$D$2+I10*'Molecular Weight'!$C$3/'Molecular Weight'!$D$3+J10*'Molecular Weight'!$C$4/'Molecular Weight'!$D$4+K10*'Molecular Weight'!$C$5/'Molecular Weight'!$D$5+L10*'Molecular Weight'!$C$6/'Molecular Weight'!$D$6+M10*'Molecular Weight'!$C$8/'Molecular Weight'!$D$8+N10*'Molecular Weight'!$C$9/'Molecular Weight'!$D$9+O10*'Molecular Weight'!$C$10/'Molecular Weight'!$D$10+P10*'Molecular Weight'!$C$11/'Molecular Weight'!$D$11+Q10*'Molecular Weight'!$C$12/'Molecular Weight'!$D$12) -> 4.6824115 | U10: =H10*T10*'Molecular Weight'!$B$2/'Molecular Weight'!$D$2 -> 2.9615785 | V10: =I10*T10*'Molecular Weight'!$B$3/'Molecular Weight'!$D$3 -> 0.05157099 | W10: =T10*J10*'Molecular Weight'!$B$4/'Molecular Weight'!$D$4 -> 1.9673843 | X10: =K10*T10*'Molecular Weight'!$B$5/'Molecular Weight'!$D$5 -> 0 | Y10: =L10*T10*'Molecular Weight'!$B$6/'Molecular Weight'!$D$6 -> 1.6763867 | Z10: =M10*T10*'Molecular Weight'!$B$8/'Molecular Weight'!$D$8 -> 0.052804189 | AA10: =N10*T10*'Molecular Weight'!$B$9/'Molecular Weight'!$D$9 -> 0.69248567 | AB10: =O10*T10*'Molecular Weight'!$B$10/'Molecular Weight'!$D$10 -> 0.58613638 | AC10: =P10*T10*'Molecular Weight'!$B$11/'Molecular Weight'!$D$11 -> 0.022664141 | AD10: =Q10*T10*'Molecular Weight'!$B$12/'Molecular Weight'!$D$12 -> 0.0069589979 | AE10: =SUM(U10:AD10) -> 8.0179699 | AF10: =IF(IF(2*12*(1-8/AE10)<0,0,2*12*(1-8/AE10))<Y10,IF(2*12*(1-8/AE10)<0,0,2*12*(1-8/AE10)),Y10) -> 0.053788947 | AG10: =AF10/Y10 -> 0.03208624 | AH10: =Y10-AF10 -> 1.6225978 | AI10: =SUM(U10,V10) -> 3.0131495 | AJ10: =SUM(AA10,AB10,Z10,Y10) -> 3.007813
A11: Auzanneau 2009 | B11: 10.1007/s00410-009-0412-7 | C11: PC3-2001-1 | D11: 2.3 | E11: 850 | F11: Metagreywacke | G11: Basaltic | H11: 38.11 | I11: 1 | J11: 21.56 | L11: 27.49 | M11: 0.74 | N11: 7.47 | O11: 3.42 | P11: 0.16 | Q11: 0.06 | R11: =SUM(H11:Q11) -> 100.01 | S11: 12 | T11: =S11/(H11*'Molecular Weight'!$C$2/'Molecular Weight'!$D$2+I11*'Molecular Weight'!$C$3/'Molecular Weight'!$D$3+J11*'Molecular Weight'!$C$4/'Molecular Weight'!$D$4+K11*'Molecular Weight'!$C$5/'Molecular Weight'!$D$5+L11*'Molecular Weight'!$C$6/'Molecular Weight'!$D$6+M11*'Molecular Weight'!$C$8/'Molecular Weight'!$D$8+N11*'Molecular Weight'!$C$9/'Molecular Weight'!$D$9+O11*'Molecular Weight'!$C$10/'Molecular Weight'!$D$10+P11*'Molecular Weight'!$C$11/'Molecular Weight'!$D$11+Q11*'Molecular Weight'!$C$12/'Molecular Weight'!$D$12) -> 4.6680087 | U11: =H11*T11*'Molecular Weight'!$B$2/'Molecular Weight'!$D$2 -> 2.9610155 | V11: =I11*T11*'Molecular Weight'!$B$3/'Molecular Weight'!$D$3 -> 0.058423138 | W11: =T11*J11*'Molecular Weight'!$B$4/'Molecular Weight'!$D$4 -> 1.974152 | X11: =K11*T11*'Molecular Weight'!$B$5/'Molecular Weight'!$D$5 -> 0 | Y11: =L11*T11*'Molecular Weight'!$B$6/'Molecular Weight'!$D$6 -> 1.7862411 | Z11: =M11*T11*'Molecular Weight'!$B$8/'Molecular Weight'!$D$8 -> 0.048693635 | AA11: =N11*T11*'Molecular Weight'!$B$9/'Molecular Weight'!$D$9 -> 0.86526116 | AB11: =O11*T11*'Molecular Weight'!$B$10/'Molecular Weight'!$D$10 -> 0.28467528 | AC11: =P11*T11*'Molecular Weight'!$B$11/'Molecular Weight'!$D$11 -> 0.024100723 | AD11: =Q11*T11*'Molecular Weight'!$B$12/'Molecular Weight'!$D$12 -> 0.0059465079 | AE11: =SUM(U11:AD11) -> 8.008509 | AF11: =IF(IF(2*12*(1-8/AE11)<0,0,2*12*(1-8/AE11))<Y11,IF(2*12*(1-8/AE11)<0,0,2*12*(1-8/AE11)),Y11) -> 0.025499857 | AG11: =AF11/Y11 -> 0.014275708 | AH11: =Y11-AF11 -> 1.7607412 | AI11: =SUM(U11,V11) -> 3.0194386 | AJ11: =SUM(AA11,AB11,Z11,Y11) -> 2.9848712
A12: Auzanneau 2009 | B12: 10.1007/s00410-009-0412-7 | C12: PC3-2000-5 | D12: 2.4 | E12: 800 | F12: Metagreywacke | G12: Basaltic | H12: 37.71 | I12: 0.82 | J12: 21.2 | L12: 30.68 | M12: 0.41 | N12: 4.64 | O12: 4.27 | P12: 0.22 | Q12: 0.05 | R12: =SUM(H12:Q12) -> 100 | S12: 12 | T12: =S12/(H12*'Molecular Weight'!$C$2/'Molecular Weight'!$D$2+I12*'Molecular Weight'!$C$3/'Molecular Weight'!$D$3+J12*'Molecular Weight'!$C$4/'Molecular Weight'!$D$4+K12*'Molecular Weight'!$C$5/'Molecular Weight'!$D$5+L12*'Molecular Weight'!$C$6/'Molecular Weight'!$D$6+M12*'Molecular Weight'!$C$8/'Molecular Weight'!$D$8+N12*'Molecular Weight'!$C$9/'Molecular Weight'!$D$9+O12*'Molecular Weight'!$C$10/'Molecular Weight'!$D$10+P12*'Molecular Weight'!$C$11/'Molecular Weight'!$D$11+Q12*'Molecular Weight'!$C$12/'Molecular Weight'!$D$12) -> 4.7471667 | U12: =H12*T12*'Molecular Weight'!$B$2/'Molecular Weight'!$D$2 -> 2.9796214 | V12: =I12*T12*'Molecular Weight'!$B$3/'Molecular Weight'!$D$3 -> 0.048719358 | W12: =T12*J12*'Molecular Weight'!$B$4/'Molecular Weight'!$D$4 -> 1.9741062 | X12: =K12*T12*'Molecular Weight'!$B$5/'Molecular Weight'!$D$5 -> 0 | Y12: =L12*T12*'Molecular Weight'!$B$6/'Molecular Weight'!$D$6 -> 2.0273256 | Z12: =M12*T12*'Molecular Weight'!$B$8/'Molecular Weight'!$D$8 -> 0.027436402 | AA12: =N12*T12*'Molecular Weight'!$B$9/'Molecular Weight'!$D$9 -> 0.54657205 | AB12: =O12*T12*'Molecular Weight'!$B$10/'Molecular Weight'!$D$10 -> 0.3614551 | AC12: =P12*T12*'Molecular Weight'!$B$11/'Molecular Weight'!$D$11 -> 0.033700441 | AD12: =Q12*T12*'Molecular Weight'!$B$12/'Molecular Weight'!$D$12 -> 0.0050394551 | AE12: =SUM(U12:AD12) -> 8.0039761 | AF12: =IF(IF(2*12*(1-8/AE12)<0,0,2*12*(1-8/AE12))<Y12,IF(2*12*(1-8/AE12)<0,0,2*12*(1-8/AE12)),Y12) -> 0.011922257 | AG12: =AF12/Y12 -> 0.0058807806 | AH12: =Y12-AF12 -> 2.0154034 | AI12: =SUM(U12,V12) -> 3.0283408 | AJ12: =SUM(AA12,AB12,Z12,Y12) -> 2.9627892
A13: Auzanneau 2009 | B13: 10.1007/s00410-009-0412-7 | C13: PC3-2000-8 | D13: 2.4 | E13: 850 | F13: Metagreywacke | G13: Basaltic | H13: 38.8 | I13: 0.62 | J13: 21.26 | L13: 29.84 | M13: 0.3 | N13: 5.91 | O13: 2.98 | P13: 0.24 | Q13: 0.06 | R13: =SUM(H13:Q13) -> 100.01 | S13: 12 | T13: =S13/(H13*'Molecular Weight'!$C$2/'Molecular Weight'!$D$2+I13*'Molecular Weight'!$C$3/'Molecular Weight'!$D$3+J13*'Molecular Weight'!$C$4/'Molecular Weight'!$D$4+K13*'Molecular Weight'!$C$5/'Molecular Weight'!$D$5+L13*'Molecular Weight'!$C$6/'Molecular Weight'!$D$6+M13*'Molecular Weight'!$C$8/'Molecular Weight'!$D$8+N13*'Molecular Weight'!$C$9/'Molecular Weight'!$D$9+O13*'Molecular Weight'!$C$10/'Molecular Weight'!$D$10+P13*'Molecular Weight'!$C$11/'Molecular Weight'!$D$11+Q13*'Molecular Weight'!$C$12/'Molecular Weight'!$D$12) -> 4.6937998 | U13: =H13*T13*'Molecular Weight'!$B$2/'Molecular Weight'!$D$2 -> 3.0312822 | V13: =I13*T13*'Molecular Weight'!$B$3/'Molecular Weight'!$D$3 -> 0.036422477 | W13: =T13*J13*'Molecular Weight'!$B$4/'Molecular Weight'!$D$4 -> 1.9574379 | X13: =K13*T13*'Molecular Weight'!$B$5/'Molecular Weight'!$D$5 -> 0 | Y13: =L13*T13*'Molecular Weight'!$B$6/'Molecular Weight'!$D$6 -> 1.9496518 | Z13: =M13*T13*'Molecular Weight'!$B$8/'Molecular Weight'!$D$8 -> 0.019849731 | AA13: =N13*T13*'Molecular Weight'!$B$9/'Molecular Weight'!$D$9 -> 0.68834633 | AB13: =O13*T13*'Molecular Weight'!$B$10/'Molecular Weight'!$D$10 -> 0.24942089 | AC13: =P13*T13*'Molecular Weight'!$B$11/'Molecular Weight'!$D$11 -> 0.036350821 | AD13: =Q13*T13*'Molecular Weight'!$B$12/'Molecular Weight'!$D$12 -> 0.0059793628 | AE13: =SUM(U13:AD13) -> 7.9747415 | AF13: =IF(IF(2*12*(1-8/AE13)<0,0,2*12*(1-8/AE13))<Y13,IF(2*12*(1-8/AE13)<0,0,2*12*(1-8/AE13)),Y13) -> 0 | AG13: =AF13/Y13 -> 0 | AH13: =Y13-AF13 -> 1.9496518 | AI13: =SUM(U13,V13) -> 3.0677046 | AJ13: =SUM(AA13,AB13,Z13,Y13) -> 2.9072688
A14: Auzanneau 2009 | B14: 10.1007/s00410-009-0412-7 | C14: PC3-2001-16 | D14: 2.4 | E14: 850 | F14: Metagreywacke | G14: Basaltic | H14: 38.47 | I14: 1.03 | J14: 20.9 | L14: 28.9 | M14: 0.47 | N14: 6.11 | O14: 3.75 | P14: 0.33 | Q14: 0.04 | R14: =SUM(H14:Q14) -> 100 | S14: 12 | T14: =S14/(H14*'Molecular Weight'!$C$2/'Molecular Weight'!$D$2+I14*'Molecular Weight'!$C$3/'Molecular Weight'!$D$3+J14*'Molecular Weight'!$C$4/'Molecular Weight'!$D$4+K14*'Molecular Weight'!$C$5/'Molecular Weight'!$D$5+L14*'Molecular Weight'!$C$6/'Molecular Weight'!$D$6+M14*'Molecular Weight'!$C$8/'Molecular Weight'!$D$8+N14*'Molecular Weight'!$C$9/'Molecular Weight'!$D$9+O14*'Molecular Weight'!$C$10/'Molecular Weight'!$D$10+P14*'Molecular Weight'!$C$11/'Molecular Weight'!$D$11+Q14*'Molecular Weight'!$C$12/'Molecular Weight'!$D$12) -> 4.6976038 | U14: =H14*T14*'Molecular Weight'!$B$2/'Molecular Weight'!$D$2 -> 3.0079364 | V14: =I14*T14*'Molecular Weight'!$B$3/'Molecular Weight'!$D$3 -> 0.060557345 | W14: =T14*J14*'Molecular Weight'!$B$4/'Molecular Weight'!$D$4 -> 1.9258517 | X14: =K14*T14*'Molecular Weight'!$B$5/'Molecular Weight'!$D$5 -> 0 | Y14: =L14*T14*'Molecular Weight'!$B$6/'Molecular Weight'!$D$6 -> 1.8897654 | Z14: =M14*T14*'Molecular Weight'!$B$8/'Molecular Weight'!$D$8 -> 0.031123115 | AA14: =N14*T14*'Molecular Weight'!$B$9/'Molecular Weight'!$D$9 -> 0.71221735 | AB14: =O14*T14*'Molecular Weight'!$B$10/'Molecular Weight'!$D$10 -> 0.31412293 | AC14: =P14*T14*'Molecular Weight'!$B$11/'Molecular Weight'!$D$11 -> 0.050022886 | AD14: =Q14*T14*'Molecular Weight'!$B$12/'Molecular Weight'!$D$12 -> 0.0039894724 | AE14: =SUM(U14:AD14) -> 7.9955866 | AF14: =IF(IF(2*12*(1-8/AE14)<0,0,2*12*(1-8/AE14))<Y14,IF(2*12*(1-8/AE14)<0,0,2*12*(1-8/AE14)),Y14) -> 0 | AG14: =AF14/Y14 -> 0 | AH14: =Y14-AF14 -> 1.8897654 | AI14: =SUM(U14,V14) -> 3.0684937 | AJ14: =SUM(AA14,AB14,Z14,Y14) -> 2.9472288
A15: Auzanneau 2009 | B15: 10.1007/s00410-009-0412-7 | C15: PC3-2001-11 | D15: 2.4 | E15: 870 | F15: Metagreywacke | G15: Basaltic | H15: 37.54 | I15: 0.85 | J15: 21.44 | L15: 27.24 | M15: 0.35 | N15: 6.74 | O15: 4.89 | P15: 0.26 | Q15: 0.06 | R15: =SUM(H15:Q15) -> 99.37 | S15: 12 | T15: =S15/(H15*'Molecular Weight'!$C$2/'Molecular Weight'!$D$2+I15*'Molecular Weight'!$C$3/'Molecular Weight'!$D$3+J15*'Molecular Weight'!$C$4/'Molecular Weight'!$D$4+K15*'Molecular Weight'!$C$5/'Molecular Weight'!$D$5+L15*'Molecular Weight'!$C$6/'Molecular Weight'!$D$6+M15*'Molecular Weight'!$C$8/'Molecular Weight'!$D$8+N15*'Molecular Weight'!$C$9/'Molecular Weight'!$D$9+O15*'Molecular Weight'!$C$10/'Molecular Weight'!$D$10+P15*'Molecular Weight'!$C$11/'Molecular Weight'!$D$11+Q15*'Molecular Weight'!$C$12/'Molecular Weight'!$D$12) -> 4.714825 | U15: =H15*T15*'Molecular Weight'!$B$2/'Molecular Weight'!$D$2 -> 2.9459809 | V15: =I15*T15*'Molecular Weight'!$B$3/'Molecular Weight'!$D$3 -> 0.050157713 | W15: =T15*J15*'Molecular Weight'!$B$4/'Molecular Weight'!$D$4 -> 1.982853 | X15: =K15*T15*'Molecular Weight'!$B$5/'Molecular Weight'!$D$5 -> 0 | Y15: =L15*T15*'Molecular Weight'!$B$6/'Molecular Weight'!$D$6 -> 1.7877482 | Z15: =M15*T15*'Molecular Weight'!$B$8/'Molecular Weight'!$D$8 -> 0.023261753 | AA15: =N15*T15*'Molecular Weight'!$B$9/'Molecular Weight'!$D$9 -> 0.78853401 | AB15: =O15*T15*'Molecular Weight'!$B$10/'Molecular Weight'!$D$10 -> 0.41111794 | AC15: =P15*T15*'Molecular Weight'!$B$11/'Molecular Weight'!$D$11 -> 0.039556454 | AD15: =Q15*T15*'Molecular Weight'!$B$12/'Molecular Weight'!$D$12 -> 0.0060061465 | AE15: =SUM(U15:AD15) -> 8.0352162 | AF15: =IF(IF(2*12*(1-8/AE15)<0,0,2*12*(1-8/AE15))<Y15,IF(2*12*(1-8/AE15)<0,0,2*12*(1-8/AE15)),Y15) -> 0.10518553 | AG15: =AF15/Y15 -> 0.058836879 | AH15: =Y15-AF15 -> 1.6825627 | AI15: =SUM(U15,V15) -> 2.9961386 | AJ15: =SUM(AA15,AB15,Z15,Y15) -> 3.0106619
A16: Auzanneau 2009 | B16: 10.1007/s00410-009-0412-7 | C16: PC3-2000-10 | D16: 2.4 | E16: 900 | F16: Metagreywacke | G16: Basaltic | H16: 38.39 | I16: 0.82 | J16: 21.45 | L16: 27.07 | M16: 0.35 | N16: 7.4 | O16: 4.15 | P16: 0.31 | Q16: 0.06 | R16: =SUM(H16:Q16) -> 100 | S16: 12 | T16: =S16/(H16*'Molecular Weight'!$C$2/'Molecular Weight'!$D$2+I16*'Molecular Weight'!$C$3/'Molecular Weight'!$D$3+J16*'Molecular Weight'!$C$4/'Molecular Weight'!$D$4+K16*'Molecular Weight'!$C$5/'Molecular Weight'!$D$5+L16*'Molecular Weight'!$C$6/'Molecular Weight'!$D$6+M16*'Molecular Weight'!$C$8/'Molecular Weight'!$D$8+N16*'Molecular Weight'!$C$9/'Molecular Weight'!$D$9+O16*'Molecular Weight'!$C$10/'Molecular Weight'!$D$10+P16*'Molecular Weight'!$C$11/'Molecular Weight'!$D$11+Q16*'Molecular Weight'!$C$12/'Molecular Weight'!$D$12) -> 4.6608741 | U16: =H16*T16*'Molecular Weight'!$B$2/'Molecular Weight'!$D$2 -> 2.9782117 | V16: =I16*T16*'Molecular Weight'!$B$3/'Molecular Weight'!$D$3 -> 0.047833752 | W16: =T16*J16*'Molecular Weight'!$B$4/'Molecular Weight'!$D$4 -> 1.9610779 | X16: =K16*T16*'Molecular Weight'!$B$5/'Molecular Weight'!$D$5 -> 0 | Y16: =L16*T16*'Molecular Weight'!$B$6/'Molecular Weight'!$D$6 -> 1.756262 | Z16: =M16*T16*'Molecular Weight'!$B$8/'Molecular Weight'!$D$8 -> 0.022995573 | AA16: =N16*T16*'Molecular Weight'!$B$9/'Molecular Weight'!$D$9 -> 0.85584289 | AB16: =O16*T16*'Molecular Weight'!$B$10/'Molecular Weight'!$D$10 -> 0.34491133 | AC16: =P16*T16*'Molecular Weight'!$B$11/'Molecular Weight'!$D$11 -> 0.046623781 | AD16: =Q16*T16*'Molecular Weight'!$B$12/'Molecular Weight'!$D$12 -> 0.0059374192 | AE16: =SUM(U16:AD16) -> 8.0196963 | AF16: =IF(IF(2*12*(1-8/AE16)<0,0,2*12*(1-8/AE16))<Y16,IF(2*12*(1-8/AE16)<0,0,2*12*(1-8/AE16)),Y16) -> 0.058943654 | AG16: =AF16/Y16 -> 0.033561994 | AH16: =Y16-AF16 -> 1.6973183 | AI16: =SUM(U16,V16) -> 3.0260454 | AJ16: =SUM(AA16,AB16,Z16,Y16) -> 2.9800118
A17: Auzanneau 2009 | B17: 10.1007/s00410-009-0412-7 | C17: PC3-2000-7 | D17: 2.8 | E17: 800 | F17: Metagreywacke | G17: Basaltic | H17: 37.75 | I17: 0.77 | J17: 21.25 | L17: 30.97 | M17: 0.5 | N17: 5.24 | O17: 3.28 | P17: 0.2 | Q17: 0.04 | R17: =SUM(H17:Q17) -> 100 | S17: 12 | T17: =S17/(H17*'Molecular Weight'!$C$2/'Molecular Weight'!$D$2+I17*'Molecular Weight'!$C$3/'Molecular Weight'!$D$3+J17*'Molecular Weight'!$C$4/'Molecular Weight'!$D$4+K17*'Molecular Weight'!$C$5/'Molecular Weight'!$D$5+L17*'Molecular Weight'!$C$6/'Molecular Weight'!$D$6+M17*'Molecular Weight'!$C$8/'Molecular Weight'!$D$8+N17*'Molecular Weight'!$C$9/'Molecular Weight'!$D$9+O17*'Molecular Weight'!$C$10/'Molecular Weight'!$D$10+P17*'Molecular Weight'!$C$11/'Molecular Weight'!$D$11+Q17*'Molecular Weight'!$C$12/'Molecular Weight'!$D$12) -> 4.7402982 | U17: =H17*T17*'Molecular Weight'!$B$2/'Molecular Weight'!$D$2 -> 2.9784663 | V17: =I17*T17*'Molecular Weight'!$B$3/'Molecular Weight'!$D$3 -> 0.045682473 | W17: =T17*J17*'Molecular Weight'!$B$4/'Molecular Weight'!$D$4 -> 1.9758991 | X17: =K17*T17*'Molecular Weight'!$B$5/'Molecular Weight'!$D$5 -> 0 | Y17: =L17*T17*'Molecular Weight'!$B$6/'Molecular Weight'!$D$6 -> 2.0435278 | Z17: =M17*T17*'Molecular Weight'!$B$8/'Molecular Weight'!$D$8 -> 0.033410616 | AA17: =N17*T17*'Molecular Weight'!$B$9/'Molecular Weight'!$D$9 -> 0.61635639 | AB17: =O17*T17*'Molecular Weight'!$B$10/'Molecular Weight'!$D$10 -> 0.27724996 | AC17: =P17*T17*'Molecular Weight'!$B$11/'Molecular Weight'!$D$11 -> 0.030592437 | AD17: =Q17*T17*'Molecular Weight'!$B$12/'Molecular Weight'!$D$12 -> 0.0040257309 | AE17: =SUM(U17:AD17) -> 8.0052108 | AF17: =IF(IF(2*12*(1-8/AE17)<0,0,2*12*(1-8/AE17))<Y17,IF(2*12*(1-8/AE17)<0,0,2*12*(1-8/AE17)),Y17) -> 0.015622106 | AG17: =AF17/Y17 -> 0.0076446753 | AH17: =Y17-AF17 -> 2.0279056 | AI17: =SUM(U17,V17) -> 3.0241488 | AJ17: =SUM(AA17,AB17,Z17,Y17) -> 2.9705447
A18: Auzanneau 2009 | B18: 10.1007/s00410-009-0412-7 | C18: PC3-2000-12 | D18: 2.8 | E18: 900 | F18: Metagreywacke | G18: Basaltic | H18: 38.51 | I18: 0.86 | J18: 21.85 | L18: 27.25 | M18: 0.45 | N18: 7.22 | O18: 3.48 | P18: 0.34 | Q18: 0.03 | R18: =SUM(H18:Q18) -> 99.99 | S18: 12 | T18: =S18/(H18*'Molecular Weight'!$C$2/'Molecular Weight'!$D$2+I18*'Molecular Weight'!$C$3/'Molecular Weight'!$D$3+J18*'Molecular Weight'!$C$4/'Molecular Weight'!$D$4+K18*'Molecular Weight'!$C$5/'Molecular Weight'!$D$5+L18*'Molecular Weight'!$C$6/'Molecular Weight'!$D$6+M18*'Molecular Weight'!$C$8/'Molecular Weight'!$D$8+N18*'Molecular Weight'!$C$9/'Molecular Weight'!$D$9+O18*'Molecular Weight'!$C$10/'Molecular Weight'!$D$10+P18*'Molecular Weight'!$C$11/'Molecular Weight'!$D$11+Q18*'Molecular Weight'!$C$12/'Molecular Weight'!$D$12) -> 4.6528641 | U18: =H18*T18*'Molecular Weight'!$B$2/'Molecular Weight'!$D$2 -> 2.9823867 | V18: =I18*T18*'Molecular Weight'!$B$3/'Molecular Weight'!$D$3 -> 0.05008089 | W18: =T18*J18*'Molecular Weight'!$B$4/'Molecular Weight'!$D$4 -> 1.994215 | X18: =K18*T18*'Molecular Weight'!$B$5/'Molecular Weight'!$D$5 -> 0 | Y18: =L18*T18*'Molecular Weight'!$B$6/'Molecular Weight'!$D$6 -> 1.7649018 | Z18: =M18*T18*'Molecular Weight'!$B$8/'Molecular Weight'!$D$8 -> 0.029514926 | AA18: =N18*T18*'Molecular Weight'!$B$9/'Molecular Weight'!$D$9 -> 0.83359004 | AB18: =O18*T18*'Molecular Weight'!$B$10/'Molecular Weight'!$D$10 -> 0.28872979 | AC18: =P18*T18*'Molecular Weight'!$B$11/'Molecular Weight'!$D$11 -> 0.051047879 | AD18: =Q18*T18*'Molecular Weight'!$B$12/'Molecular Weight'!$D$12 -> 0.0029636077 | AE18: =SUM(U18:AD18) -> 7.9974306 | AF18: =IF(IF(2*12*(1-8/AE18)<0,0,2*12*(1-8/AE18))<Y18,IF(2*12*(1-8/AE18)<0,0,2*12*(1-8/AE18)),Y18) -> 0 | AG18: =AF18/Y18 -> 0 | AH18: =Y18-AF18 -> 1.7649018 | AI18: =SUM(U18,V18) -> 3.0324676 | AJ18: =SUM(AA18,AB18,Z18,Y18) -> 2.9167366
A19: Auzanneau 2009 | B19: 10.1007/s00410-009-0412-7 | C19: PC3-2000-3 | D19: 2.8 | E19: 950 | F19: Metagreywacke | G19: Basaltic | H19: 37.68 | I19: 1.96 | J19: 21.3 | L19: 24.83 | M19: 0.45 | N19: 7.7 | O19: 5.82 | P19: 0.23 | Q19: 0.03 | R19: =SUM(H19:Q19) -> 100 | S19: 12 | T19: =S19/(H19*'Molecular Weight'!$C$2/'Molecular Weight'!$D$2+I19*'Molecular Weight'!$C$3/'Molecular Weight'!$D$3+J19*'Molecular Weight'!$C$4/'Molecular Weight'!$D$4+K19*'Molecular Weight'!$C$5/'Molecular Weight'!$D$5+L19*'Molecular Weight'!$C$6/'Molecular Weight'!$D$6+M19*'Molecular Weight'!$C$8/'Molecular Weight'!$D$8+N19*'Molecular Weight'!$C$9/'Molecular Weight'!$D$9+O19*'Molecular Weight'!$C$10/'Molecular Weight'!$D$10+P19*'Molecular Weight'!$C$11/'Molecular Weight'!$D$11+Q19*'Molecular Weight'!$C$12/'Molecular Weight'!$D$12) -> 4.6494427 | U19: =H19*T19*'Molecular Weight'!$B$2/'Molecular Weight'!$D$2 -> 2.9159621 | V19: =I19*T19*'Molecular Weight'!$B$3/'Molecular Weight'!$D$3 -> 0.11405391 | W19: =T19*J19*'Molecular Weight'!$B$4/'Molecular Weight'!$D$4 -> 1.9425879 | X19: =K19*T19*'Molecular Weight'!$B$5/'Molecular Weight'!$D$5 -> 0 | Y19: =L19*T19*'Molecular Weight'!$B$6/'Molecular Weight'!$D$6 -> 1.6069831 | Z19: =M19*T19*'Molecular Weight'!$B$8/'Molecular Weight'!$D$8 -> 0.029493223 | AA19: =N19*T19*'Molecular Weight'!$B$9/'Molecular Weight'!$D$9 -> 0.88835506 | AB19: =O19*T19*'Molecular Weight'!$B$10/'Molecular Weight'!$D$10 -> 0.48252063 | AC19: =P19*T19*'Molecular Weight'!$B$11/'Molecular Weight'!$D$11 -> 0.034506997 | AD19: =Q19*T19*'Molecular Weight'!$B$12/'Molecular Weight'!$D$12 -> 0.0029614285 | AE19: =SUM(U19:AD19) -> 8.0174243 | AF19: =IF(IF(2*12*(1-8/AE19)<0,0,2*12*(1-8/AE19))<Y19,IF(2*12*(1-8/AE19)<0,0,2*12*(1-8/AE19)),Y19) -> 0.052159217 | AG19: =AF19/Y19 -> 0.032457851 | AH19: =Y19-AF19 -> 1.5548238 | AI19: =SUM(U19,V19) -> 3.030016 | AJ19: =SUM(AA19,AB19,Z19,Y19) -> 3.007352
... A55: Auzanneau 2009 | B55: 10.1007/s00410-009-0412-7 | C55: ME211 | D55: 8 | E55: 900 | F55: Metagreywacke | G55: Basaltic | H55: 38.9 | I55: 0.22 | J55: 21.83 | L55: 25.07 | M55: 0.32 | N55: 6.64 | O55: 6.82 | P55: 0.13 | Q55: 0.02 | R55: =SUM(H55:Q55) -> 99.95 | S55: 12 | T55: =S55/(H55*'Molecular Weight'!$C$2/'Molecular Weight'!$D$2+I55*'Molecular Weight'!$C$3/'Molecular Weight'!$D$3+J55*'Molecular Weight'!$C$4/'Molecular Weight'!$D$4+K55*'Molecular Weight'!$C$5/'Molecular Weight'!$D$5+L55*'Molecular Weight'!$C$6/'Molecular Weight'!$D$6+M55*'Molecular Weight'!$C$8/'Molecular Weight'!$D$8+N55*'Molecular Weight'!$C$9/'Molecular Weight'!$D$9+O55*'Molecular Weight'!$C$10/'Molecular Weight'!$D$10+P55*'Molecular Weight'!$C$11/'Molecular Weight'!$D$11+Q55*'Molecular Weight'!$C$12/'Molecular Weight'!$D$12) -> 4.642302 | U55: =H55*T55*'Molecular Weight'!$B$2/'Molecular Weight'!$D$2 -> 3.0057514 | V55: =I55*T55*'Molecular Weight'!$B$3/'Molecular Weight'!$D$3 -> 0.012782308 | W55: =T55*J55*'Molecular Weight'!$B$4/'Molecular Weight'!$D$4 -> 1.9878669 | X55: =K55*T55*'Molecular Weight'!$B$5/'Molecular Weight'!$D$5 -> 0 | Y55: =L55*T55*'Molecular Weight'!$B$6/'Molecular Weight'!$D$6 -> 1.6200238 | Z55: =M55*T55*'Molecular Weight'!$B$8/'Molecular Weight'!$D$8 -> 0.020940748 | AA55: =N55*T55*'Molecular Weight'!$B$9/'Molecular Weight'!$D$9 -> 0.76488549 | AB55: =O55*T55*'Molecular Weight'!$B$10/'Molecular Weight'!$D$10 -> 0.56455955 | AC55: =P55*T55*'Molecular Weight'!$B$11/'Molecular Weight'!$D$11 -> 0.019474 | AD55: =Q55*T55*'Molecular Weight'!$B$12/'Molecular Weight'!$D$12 -> 0.0019712535 | AE55: =SUM(U55:AD55) -> 7.9982554 | AF55: =IF(IF(2*12*(1-8/AE55)<0,0,2*12*(1-8/AE55))<Y55,IF(2*12*(1-8/AE55)<0,0,2*12*(1-8/AE55)),Y55) -> 0 | AG55: =AF55/Y55 -> 0 | AH55: =Y55-AF55 -> 1.6200238 | AI55: =SUM(U55,V55) -> 3.0185338 | AJ55: =SUM(AA55,AB55,Z55,Y55) -> 2.9704096
A56: Ardia et al. (2012) | B56: 10.1016/j.epsl.2012.05.038 | C56: M446 | D56: 5 | E56: 1400 | F56: Peridotite | G56: Peridotitic | H56: 43.13 | I56: 0.26 | J56: 22.08 | K56: 1.84 | L56: 6.05 | M56: 0.2 | N56: 22.66 | O56: 5.08 | P56: 0.02 | Q56: 0 | R56: =SUM(H56:Q56) -> 101.32 | S56: 12 | T56: =S56/(H56*'Molecular Weight'!$C$2/'Molecular Weight'!$D$2+I56*'Molecular Weight'!$C$3/'Molecular Weight'!$D$3+J56*'Molecular Weight'!$C$4/'Molecular Weight'!$D$4+K56*'Molecular Weight'!$C$5/'Molecular Weight'!$D$5+L56*'Molecular Weight'!$C$6/'Molecular Weight'!$D$6+M56*'Molecular Weight'!$C$8/'Molecular Weight'!$D$8+N56*'Molecular Weight'!$C$9/'Molecular Weight'!$D$9+O56*'Molecular Weight'!$C$10/'Molecular Weight'!$D$10+P56*'Molecular Weight'!$C$11/'Molecular Weight'!$D$11+Q56*'Molecular Weight'!$C$12/'Molecular Weight'!$D$12) -> 4.1834151 | U56: =H56*T56*'Molecular Weight'!$B$2/'Molecular Weight'!$D$2 -> 3.003174 | V56: =I56*T56*'Molecular Weight'!$B$3/'Molecular Weight'!$D$3 -> 0.013613115 | W56: =T56*J56*'Molecular Weight'!$B$4/'Molecular Weight'!$D$4 -> 1.8118832 | X56: =K56*T56*'Molecular Weight'!$B$5/'Molecular Weight'!$D$5 -> 0.10128935 | Y56: =L56*T56*'Molecular Weight'!$B$6/'Molecular Weight'!$D$6 -> 0.35230598 | Z56: =M56*T56*'Molecular Weight'!$B$8/'Molecular Weight'!$D$8 -> 0.011794235 | AA56: =N56*T56*'Molecular Weight'!$B$9/'Molecular Weight'!$D$9 -> 2.3522627 | AB56: =O56*T56*'Molecular Weight'!$B$10/'Molecular Weight'!$D$10 -> 0.37895415 | AC56: =P56*T56*'Molecular Weight'!$B$11/'Molecular Weight'!$D$11 -> 0.0026998484 | AD56: =Q56*T56*'Molecular Weight'!$B$12/'Molecular Weight'!$D$12 -> 0 | AE56: =SUM(U56:AD56) -> 8.0279765 | AF56: =IF(IF(2*12*(1-8/AE56)<0,0,2*12*(1-8/AE56))<Y56,IF(2*12*(1-8/AE56)<0,0,2*12*(1-8/AE56)),Y56) -> 0.083637152 | AG56: =AF56/Y56 -> 0.23739919 | AH56: =Y56-AF56 -> 0.26866882 | AI56: =SUM(U56,V56) -> 3.0167871 | AJ56: =SUM(AA56,AB56,Z56,Y56) -> 3.095317
A57: Ardia et al. (2012) | B57: 10.1016/j.epsl.2012.05.038 | C57: M435 | D57: 5 | E57: 1400 | F57: Peridotite | G57: Peridotitic | H57: 41.36 | I57: 0.2 | J57: 22.87 | K57: 1.35 | L57: 6.48 | M57: 0.24 | N57: 21.13 | O57: 5.26 | P57: 0.02 | Q57: 0.03 | R57: =SUM(H57:Q57) -> 98.94 | S57: 12 | T57: =S57/(H57*'Molecular Weight'!$C$2/'Molecular Weight'!$D$2+I57*'Molecular Weight'!$C$3/'Molecular Weight'!$D$3+J57*'Molecular Weight'!$C$4/'Molecular Weight'!$D$4+K57*'Molecular Weight'!$C$5/'Molecular Weight'!$D$5+L57*'Molecular Weight'!$C$6/'Molecular Weight'!$D$6+M57*'Molecular Weight'!$C$8/'Molecular Weight'!$D$8+N57*'Molecular Weight'!$C$9/'Molecular Weight'!$D$9+O57*'Molecular Weight'!$C$10/'Molecular Weight'!$D$10+P57*'Molecular Weight'!$C$11/'Molecular Weight'!$D$11+Q57*'Molecular Weight'!$C$12/'Molecular Weight'!$D$12) -> 4.2953304 | U57: =H57*T57*'Molecular Weight'!$B$2/'Molecular Weight'!$D$2 -> 2.9569718 | V57: =I57*T57*'Molecular Weight'!$B$3/'Molecular Weight'!$D$3 -> 0.010751766 | W57: =T57*J57*'Molecular Weight'!$B$4/'Molecular Weight'!$D$4 -> 1.9269166 | X57: =K57*T57*'Molecular Weight'!$B$5/'Molecular Weight'!$D$5 -> 0.076303652 | Y57: =L57*T57*'Molecular Weight'!$B$6/'Molecular Weight'!$D$6 -> 0.38744072 | Z57: =M57*T57*'Molecular Weight'!$B$8/'Molecular Weight'!$D$8 -> 0.014531707 | AA57: =N57*T57*'Molecular Weight'!$B$9/'Molecular Weight'!$D$9 -> 2.2521174 | AB57: =O57*T57*'Molecular Weight'!$B$10/'Molecular Weight'!$D$10 -> 0.40287871 | AC57: =P57*T57*'Molecular Weight'!$B$11/'Molecular Weight'!$D$11 -> 0.0027720751 | AD57: =Q57*T57*'Molecular Weight'!$B$12/'Molecular Weight'!$D$12 -> 0.0027358792 | AE57: =SUM(U57:AD57) -> 8.0334203 | AF57: =IF(IF(2*12*(1-8/AE57)<0,0,2*12*(1-8/AE57))<Y57,IF(2*12*(1-8/AE57)<0,0,2*12*(1-8/AE57)),Y57) -> 0.099843782 | AG57: =AF57/Y57 -> 0.2577008 | AH57: =Y57-AF57 -> 0.28759694 | AI57: =SUM(U57,V57) -> 2.9677236 | AJ57: =SUM(AA57,AB57,Z57,Y57) -> 3.0569685
A58: Ardia et al. (2012) | B58: 10.1016/j.epsl.2012.05.038 | C58: M439 | D58: 5 | E58: 1400 | F58: Peridotite | G58: Peridotitic | H58: 39.64 | I58: 0.3 | J58: 19.26 | K58: 1.46 | L58: 5.93 | M58: 0.19 | N58: 20.17 | O58: 5.34 | P58: 0.5 | Q58: 0.12 | R58: =SUM(H58:Q58) -> 92.91 | S58: 12 | T58: =S58/(H58*'Molecular Weight'!$C$2/'Molecular Weight'!$D$2+I58*'Molecular Weight'!$C$3/'Molecular Weight'!$D$3+J58*'Molecular Weight'!$C$4/'Molecular Weight'!$D$4+K58*'Molecular Weight'!$C$5/'Molecular Weight'!$D$5+L58*'Molecular Weight'!$C$6/'Molecular Weight'!$D$6+M58*'Molecular Weight'!$C$8/'Molecular Weight'!$D$8+N58*'Molecular Weight'!$C$9/'Molecular Weight'!$D$9+O58*'Molecular Weight'!$C$10/'Molecular Weight'!$D$10+P58*'Molecular Weight'!$C$11/'Molecular Weight'!$D$11+Q58*'Molecular Weight'!$C$12/'Molecular Weight'!$D$12) -> 4.5926421 | U58: =H58*T58*'Molecular Weight'!$B$2/'Molecular Weight'!$D$2 -> 3.0301653 | V58: =I58*T58*'Molecular Weight'!$B$3/'Molecular Weight'!$D$3 -> 0.017243963 | W58: =T58*J58*'Molecular Weight'!$B$4/'Molecular Weight'!$D$4 -> 1.7350782 | X58: =K58*T58*'Molecular Weight'!$B$5/'Molecular Weight'!$D$5 -> 0.088232877 | Y58: =L58*T58*'Molecular Weight'!$B$6/'Molecular Weight'!$D$6 -> 0.37909755 | Z58: =M58*T58*'Molecular Weight'!$B$8/'Molecular Weight'!$D$8 -> 0.012300564 | AA58: =N58*T58*'Molecular Weight'!$B$9/'Molecular Weight'!$D$9 -> 2.2986003 | AB58: =O58*T58*'Molecular Weight'!$B$10/'Molecular Weight'!$D$10 -> 0.43731649 | AC58: =P58*T58*'Molecular Weight'!$B$11/'Molecular Weight'!$D$11 -> 0.074098776 | AD58: =Q58*T58*'Molecular Weight'!$B$12/'Molecular Weight'!$D$12 -> 0.011700999 | AE58: =SUM(U58:AD58) -> 8.083835 | AF58: =IF(IF(2*12*(1-8/AE58)<0,0,2*12*(1-8/AE58))<Y58,IF(2*12*(1-8/AE58)<0,0,2*12*(1-8/AE58)),Y58) -> 0.24889685 | AG58: =AF58/Y58 -> 0.65655094 | AH58: =Y58-AF58 -> 0.13020069 | AI58: =SUM(U58,V58) -> 3.0474093 | AJ58: =SUM(AA58,AB58,Z58,Y58) -> 3.1273149
A59: Ardia et al. (2012) | B59: 10.1016/j.epsl.2012.05.038 | C59: M453 | D59: 5 | E59: 1450 | F59: Peridotite | G59: Peridotitic | H59: 43.75 | I59: 0.15 | J59: 23.31 | K59: 1.8 | L59: 4.94 | M59: 0.16 | N59: 23.14 | O59: 4.61 | P59: 0.01 | Q59: 0 | R59: =SUM(H59:Q59) -> 101.87 | S59: 12 | T59: =S59/(H59*'Molecular Weight'!$C$2/'Molecular Weight'!$D$2+I59*'Molecular Weight'!$C$3/'Molecular Weight'!$D$3+J59*'Molecular Weight'!$C$4/'Molecular Weight'!$D$4+K59*'Molecular Weight'!$C$5/'Molecular Weight'!$D$5+L59*'Molecular Weight'!$C$6/'Molecular Weight'!$D$6+M59*'Molecular Weight'!$C$8/'Molecular Weight'!$D$8+N59*'Molecular Weight'!$C$9/'Molecular Weight'!$D$9+O59*'Molecular Weight'!$C$10/'Molecular Weight'!$D$10+P59*'Molecular Weight'!$C$11/'Molecular Weight'!$D$11+Q59*'Molecular Weight'!$C$12/'Molecular Weight'!$D$12) -> 4.1249726 | U59: =H59*T59*'Molecular Weight'!$B$2/'Molecular Weight'!$D$2 -> 3.0037874 | V59: =I59*T59*'Molecular Weight'!$B$3/'Molecular Weight'!$D$3 -> 0.0077440036 | W59: =T59*J59*'Molecular Weight'!$B$4/'Molecular Weight'!$D$4 -> 1.8860948 | X59: =K59*T59*'Molecular Weight'!$B$5/'Molecular Weight'!$D$5 -> 0.097703147 | Y59: =L59*T59*'Molecular Weight'!$B$6/'Molecular Weight'!$D$6 -> 0.28364928 | Z59: =M59*T59*'Molecular Weight'!$B$8/'Molecular Weight'!$D$8 -> 0.009303575 | AA59: =N59*T59*'Molecular Weight'!$B$9/'Molecular Weight'!$D$9 -> 2.3685326 | AB59: =O59*T59*'Molecular Weight'!$B$10/'Molecular Weight'!$D$10 -> 0.33908922 | AC59: =P59*T59*'Molecular Weight'!$B$11/'Molecular Weight'!$D$11 -> 0.0013310657 | AD59: =Q59*T59*'Molecular Weight'!$B$12/'Molecular Weight'!$D$12 -> 0 | AE59: =SUM(U59:AD59) -> 7.9972351 | AF59: =IF(IF(2*12*(1-8/AE59)<0,0,2*12*(1-8/AE59))<Y59,IF(2*12*(1-8/AE59)<0,0,2*12*(1-8/AE59)),Y59) -> 0 | AG59: =AF59/Y59 -> 0 | AH59: =Y59-AF59 -> 0.28364928 | AI59: =SUM(U59,V59) -> 3.0115315 | AJ59: =SUM(AA59,AB59,Z59,Y59) -> 3.0005747
A60: Ardia et al. (2012) | B60: 10.1016/j.epsl.2012.05.038 | C60: M462 | D60: 5 | E60: 1500 | F60: Peridotite | G60: Peridotitic | H60: 43.08 | I60: 0.16 | J60: 22.78 | K60: 1.8 | L60: 4.44 | M60: 0.13 | N60: 24.4 | O60: 2.88 | P60: 0.03 | Q60: 0.02 | R60: =SUM(H60:Q60) -> 99.72 | S60: 12 | T60: =S60/(H60*'Molecular Weight'!$C$2/'Molecular Weight'!$D$2+I60*'Molecular Weight'!$C$3/'Molecular Weight'!$D$3+J60*'Molecular Weight'!$C$4/'Molecular Weight'!$D$4+K60*'Molecular Weight'!$C$5/'Molecular Weight'!$D$5+L60*'Molecular Weight'!$C$6/'Molecular Weight'!$D$6+M60*'Molecular Weight'!$C$8/'Molecular Weight'!$D$8+N60*'Molecular Weight'!$C$9/'Molecular Weight'!$D$9+O60*'Molecular Weight'!$C$10/'Molecular Weight'!$D$10+P60*'Molecular Weight'!$C$11/'Molecular Weight'!$D$11+Q60*'Molecular Weight'!$C$12/'Molecular Weight'!$D$12) -> 4.1884356 | U60: =H60*T60*'Molecular Weight'!$B$2/'Molecular Weight'!$D$2 -> 3.0032923 | V60: =I60*T60*'Molecular Weight'!$B$3/'Molecular Weight'!$D$3 -> 0.0083873553 | W60: =T60*J60*'Molecular Weight'!$B$4/'Molecular Weight'!$D$4 -> 1.8715685 | X60: =K60*T60*'Molecular Weight'!$B$5/'Molecular Weight'!$D$5 -> 0.099206316 | Y60: =L60*T60*'Molecular Weight'!$B$6/'Molecular Weight'!$D$6 -> 0.25886211 | Z60: =M60*T60*'Molecular Weight'!$B$8/'Molecular Weight'!$D$8 -> 0.0076754528 | AA60: =N60*T60*'Molecular Weight'!$B$9/'Molecular Weight'!$D$9 -> 2.5359262 | AB60: =O60*T60*'Molecular Weight'!$B$10/'Molecular Weight'!$D$10 -> 0.21509797 | AC60: =P60*T60*'Molecular Weight'!$B$11/'Molecular Weight'!$D$11 -> 0.0040546327 | AD60: =Q60*T60*'Molecular Weight'!$B$12/'Molecular Weight'!$D$12 -> 0.0017785289 | AE60: =SUM(U60:AD60) -> 8.0058495 | AF60: =IF(IF(2*12*(1-8/AE60)<0,0,2*12*(1-8/AE60))<Y60,IF(2*12*(1-8/AE60)<0,0,2*12*(1-8/AE60)),Y60) -> 0.017535585 | AG60: =AF60/Y60 -> 0.067741025 | AH60: =Y60-AF60 -> 0.24132652 | AI60: =SUM(U60,V60) -> 3.0116797 | AJ60: =SUM(AA60,AB60,Z60,Y60) -> 3.0175618
A61: Ardia et al. (2012) | B61: 10.1016/j.epsl.2012.05.038 | C61: M454 | D61: 6 | E61: 1450 | F61: Peridotite | G61: Peridotitic | H61: 43.78 | I61: 0.3 | J61: 22.09 | K61: 1.82 | L61: 6.51 | M61: 0.18 | N61: 22.49 | O61: 4.64 | P61: 0.04 | Q61: 0.01 | R61: =SUM(H61:Q61) -> 101.86 | S61: 12 | T61: =S61/(H61*'Molecular Weight'!$C$2/'Molecular Weight'!$D$2+I61*'Molecular Weight'!$C$3/'Molecular Weight'!$D$3+J61*'Molecular Weight'!$C$4/'Molecular Weight'!$D$4+K61*'Molecular Weight'!$C$5/'Molecular Weight'!$D$5+L61*'Molecular Weight'!$C$6/'Molecular Weight'!$D$6+M61*'Molecular Weight'!$C$8/'Molecular Weight'!$D$8+N61*'Molecular Weight'!$C$9/'Molecular Weight'!$D$9+O61*'Molecular Weight'!$C$10/'Molecular Weight'!$D$10+P61*'Molecular Weight'!$C$11/'Molecular Weight'!$D$11+Q61*'Molecular Weight'!$C$12/'Molecular Weight'!$D$12) -> 4.1587332 | U61: =H61*T61*'Molecular Weight'!$B$2/'Molecular Weight'!$D$2 -> 3.0304484 | V61: =I61*T61*'Molecular Weight'!$B$3/'Molecular Weight'!$D$3 -> 0.015614768 | W61: =T61*J61*'Molecular Weight'!$B$4/'Molecular Weight'!$D$4 -> 1.8020089 | X61: =K61*T61*'Molecular Weight'!$B$5/'Molecular Weight'!$D$5 -> 0.099597268 | Y61: =L61*T61*'Molecular Weight'!$B$6/'Molecular Weight'!$D$6 -> 0.37685625 | Z61: =M61*T61*'Molecular Weight'!$B$8/'Molecular Weight'!$D$8 -> 0.010552185 | AA61: =N61*T61*'Molecular Weight'!$B$9/'Molecular Weight'!$D$9 -> 2.3208414 | AB61: =O61*T61*'Molecular Weight'!$B$10/'Molecular Weight'!$D$10 -> 0.34408919 | AC61: =P61*T61*'Molecular Weight'!$B$11/'Molecular Weight'!$D$11 -> 0.0053678389 | AD61: =Q61*T61*'Molecular Weight'!$B$12/'Molecular Weight'!$D$12 -> 0.00088295821 | AE61: =SUM(U61:AD61) -> 8.0062592 | AF61: =IF(IF(2*12*(1-8/AE61)<0,0,2*12*(1-8/AE61))<Y61,IF(2*12*(1-8/AE61)<0,0,2*12*(1-8/AE61)),Y61) -> 0.018762815 | AG61: =AF61/Y61 -> 0.049787724 | AH61: =Y61-AF61 -> 0.35809343 | AI61: =SUM(U61,V61) -> 3.0460631 | AJ61: =SUM(AA61,AB61,Z61,Y61) -> 3.052339
A62: Ardia et al. (2012) | B62: 10.1016/j.epsl.2012.05.038 | C62: M466 | D62: 6 | E62: 1450 | F62: Peridotite | G62: Peridotitic | H62: 42.9 | I62: 0.2 | J62: 22 | K62: 1.58 | L62: 6.9 | M62: 0.15 | N62: 22.2 | O62: 4.4 | P62: 0.05 | Q62: 0.02 | R62: =SUM(H62:Q62) -> 100.4 | S62: 12 | T62: =S62/(H62*'Molecular Weight'!$C$2/'Molecular Weight'!$D$2+I62*'Molecular Weight'!$C$3/'Molecular Weight'!$D$3+J62*'Molecular Weight'!$C$4/'Molecular Weight'!$D$4+K62*'Molecular Weight'!$C$5/'Molecular Weight'!$D$5+L62*'Molecular Weight'!$C$6/'Molecular Weight'!$D$6+M62*'Molecular Weight'!$C$8/'Molecular Weight'!$D$8+N62*'Molecular Weight'!$C$9/'Molecular Weight'!$D$9+O62*'Molecular Weight'!$C$10/'Molecular Weight'!$D$10+P62*'Molecular Weight'!$C$11/'Molecular Weight'!$D$11+Q62*'Molecular Weight'!$C$12/'Molecular Weight'!$D$12) -> 4.2251897 | U62: =H62*T62*'Molecular Weight'!$B$2/'Molecular Weight'!$D$2 -> 3.016988 | V62: =I62*T62*'Molecular Weight'!$B$3/'Molecular Weight'!$D$3 -> 0.010576195 | W62: =T62*J62*'Molecular Weight'!$B$4/'Molecular Weight'!$D$4 -> 1.8233459 | X62: =K62*T62*'Molecular Weight'!$B$5/'Molecular Weight'!$D$5 -> 0.08784525 | Y62: =L62*T62*'Molecular Weight'!$B$6/'Molecular Weight'!$D$6 -> 0.40581583 | Z62: =M62*T62*'Molecular Weight'!$B$8/'Molecular Weight'!$D$8 -> 0.008934007 | AA62: =N62*T62*'Molecular Weight'!$B$9/'Molecular Weight'!$D$9 -> 2.3275239 | AB62: =O62*T62*'Molecular Weight'!$B$10/'Molecular Weight'!$D$10 -> 0.33150561 | AC62: =P62*T62*'Molecular Weight'!$B$11/'Molecular Weight'!$D$11 -> 0.0068170212 | AD62: =Q62*T62*'Molecular Weight'!$B$12/'Molecular Weight'!$D$12 -> 0.0017941358 | AE62: =SUM(U62:AD62) -> 8.0211458 | AF62: =IF(IF(2*12*(1-8/AE62)<0,0,2*12*(1-8/AE62))<Y62,IF(2*12*(1-8/AE62)<0,0,2*12*(1-8/AE62)),Y62) -> 0.063270196 | AG62: =AF62/Y62 -> 0.15590865 | AH62: =Y62-AF62 -> 0.34254563 | AI62: =SUM(U62,V62) -> 3.0275642 | AJ62: =SUM(AA62,AB62,Z62,Y62) -> 3.0737793
A63: Ardia et al. (2012) | B63: 10.1016/j.epsl.2012.05.038 | C63: M464 | D63: 6 | E63: 1450 | F63: Peridotite | G63: Peridotitic | H63: 42.3 | I63: 0.2 | J63: 21.3 | K63: 1.6 | L63: 7.4 | M63: 0.17 | N63: 21.9 | O63: 4.44 | P63: 0.05 | Q63: 0.02 | R63: =SUM(H63:Q63) -> 99.38 | S63: 12 | T63: =S63/(H63*'Molecular Weight'!$C$2/'Molecular Weight'!$D$2+I63*'Molecular Weight'!$C$3/'Molecular Weight'!$D$3+J63*'Molecular Weight'!$C$4/'Molecular Weight'!$D$4+K63*'Molecular Weight'!$C$5/'Molecular Weight'!$D$5+L63*'Molecular Weight'!$C$6/'Molecular Weight'!$D$6+M63*'Molecular Weight'!$C$8/'Molecular Weight'!$D$8+N63*'Molecular Weight'!$C$9/'Molecular Weight'!$D$9+O63*'Molecular Weight'!$C$10/'Molecular Weight'!$D$10+P63*'Molecular Weight'!$C$11/'Molecular Weight'!$D$11+Q63*'Molecular Weight'!$C$12/'Molecular Weight'!$D$12) -> 4.285033 | U63: =H63*T63*'Molecular Weight'!$B$2/'Molecular Weight'!$D$2 -> 3.0169257 | V63: =I63*T63*'Molecular Weight'!$B$3/'Molecular Weight'!$D$3 -> 0.01072599 | W63: =T63*J63*'Molecular Weight'!$B$4/'Molecular Weight'!$D$4 -> 1.7903335 | X63: =K63*T63*'Molecular Weight'!$B$5/'Molecular Weight'!$D$5 -> 0.090217157 | Y63: =L63*T63*'Molecular Weight'!$B$6/'Molecular Weight'!$D$6 -> 0.44138703 | Z63: =M63*T63*'Molecular Weight'!$B$8/'Molecular Weight'!$D$8 -> 0.010268616 | AA63: =N63*T63*'Molecular Weight'!$B$9/'Molecular Weight'!$D$9 -> 2.3285911 | AB63: =O63*T63*'Molecular Weight'!$B$10/'Molecular Weight'!$D$10 -> 0.33925725 | AC63: =P63*T63*'Molecular Weight'!$B$11/'Molecular Weight'!$D$11 -> 0.0069135737 | AD63: =Q63*T63*'Molecular Weight'!$B$12/'Molecular Weight'!$D$12 -> 0.0018195469 | AE63: =SUM(U63:AD63) -> 8.0364395 | AF63: =IF(IF(2*12*(1-8/AE63)<0,0,2*12*(1-8/AE63))<Y63,IF(2*12*(1-8/AE63)<0,0,2*12*(1-8/AE63)),Y63) -> 0.1088229 | AG63: =AF63/Y63 -> 0.24654757 | AH63: =Y63-AF63 -> 0.33256413 | AI63: =SUM(U63,V63) -> 3.0276517 | AJ63: =SUM(AA63,AB63,Z63,Y63) -> 3.119504
A64: Ardia et al. (2012) | B64: 10.1016/j.epsl.2012.05.038 | C64: M456 | D64: 7 | E64: 1450 | F64: Peridotite | G64: Peridotitic | H64: 42.8 | I64: 0.3 | J64: 21.4 | K64: 1.83 | L64: 6.7 | M64: 0.15 | N64: 22.9 | O64: 4.6 | P64: 0.15 | Q64: 0.02 | R64: =SUM(H64:Q64) -> 100.85 | S64: 12 | T64: =S64/(H64*'Molecular Weight'!$C$2/'Molecular Weight'!$D$2+I64*'Molecular Weight'!$C$3/'Molecular Weight'!$D$3+J64*'Molecular Weight'!$C$4/'Molecular Weight'!$D$4+K64*'Molecular Weight'!$C$5/'Molecular Weight'!$D$5+L64*'Molecular Weight'!$C$6/'Molecular Weight'!$D$6+M64*'Molecular Weight'!$C$8/'Molecular Weight'!$D$8+N64*'Molecular Weight'!$C$9/'Molecular Weight'!$D$9+O64*'Molecular Weight'!$C$10/'Molecular Weight'!$D$10+P64*'Molecular Weight'!$C$11/'Molecular Weight'!$D$11+Q64*'Molecular Weight'!$C$12/'Molecular Weight'!$D$12) -> 4.2159561 | U64: =H64*T64*'Molecular Weight'!$B$2/'Molecular Weight'!$D$2 -> 3.0033775 | V64: =I64*T64*'Molecular Weight'!$B$3/'Molecular Weight'!$D$3 -> 0.015829622 | W64: =T64*J64*'Molecular Weight'!$B$4/'Molecular Weight'!$D$4 -> 1.7697423 | X64: =K64*T64*'Molecular Weight'!$B$5/'Molecular Weight'!$D$5 -> 0.10152246 | Y64: =L64*T64*'Molecular Weight'!$B$6/'Molecular Weight'!$D$6 -> 0.3931919 | Z64: =M64*T64*'Molecular Weight'!$B$8/'Molecular Weight'!$D$8 -> 0.0089144828 | AA64: =N64*T64*'Molecular Weight'!$B$9/'Molecular Weight'!$D$9 -> 2.3956674 | AB64: =O64*T64*'Molecular Weight'!$B$10/'Molecular Weight'!$D$10 -> 0.34581665 | AC64: =P64*T64*'Molecular Weight'!$B$11/'Molecular Weight'!$D$11 -> 0.02040637 | AD64: =Q64*T64*'Molecular Weight'!$B$12/'Molecular Weight'!$D$12 -> 0.0017902149 | AE64: =SUM(U64:AD64) -> 8.0562588 | AF64: =IF(IF(2*12*(1-8/AE64)<0,0,2*12*(1-8/AE64))<Y64,IF(2*12*(1-8/AE64)<0,0,2*12*(1-8/AE64)),Y64) -> 0.16759782 | AG64: =AF64/Y64 -> 0.42624944 | AH64: =Y64-AF64 -> 0.22559407 | AI64: =SUM(U64,V64) -> 3.0192071 | AJ64: =SUM(AA64,AB64,Z64,Y64) -> 3.1435904
A65: Ardia et al. (2012) | B65: 10.1016/j.epsl.2012.05.038 | C65: M460 | D65: 8 | E65: 1450 | F65: Peridotite | G65: Peridotitic | H65: 43.3 | I65: 0.28 | J65: 21.45 | K65: 1.72 | L65: 4.17 | M65: 0.18 | N65: 23.86 | O65: 4.35 | P65: 0.13 | Q65: 0.03 | R65: =SUM(H65:Q65) -> 99.47 | S65: 12 | T65: =S65/(H65*'Molecular Weight'!$C$2/'Molecular Weight'!$D$2+I65*'Molecular Weight'!$C$3/'Molecular Weight'!$D$3+J65*'Molecular Weight'!$C$4/'Molecular Weight'!$D$4+K65*'Molecular Weight'!$C$5/'Molecular Weight'!$D$5+L65*'Molecular Weight'!$C$6/'Molecular Weight'!$D$6+M65*'Molecular Weight'!$C$8/'Molecular Weight'!$D$8+N65*'Molecular Weight'!$C$9/'Molecular Weight'!$D$9+O65*'Molecular Weight'!$C$10/'Molecular Weight'!$D$10+P65*'Molecular Weight'!$C$11/'Molecular Weight'!$D$11+Q65*'Molecular Weight'!$C$12/'Molecular Weight'!$D$12) -> 4.2162576 | U65: =H65*T65*'Molecular Weight'!$B$2/'Molecular Weight'!$D$2 -> 3.038681 | V65: =I65*T65*'Molecular Weight'!$B$3/'Molecular Weight'!$D$3 -> 0.014775371 | W65: =T65*J65*'Molecular Weight'!$B$4/'Molecular Weight'!$D$4 -> 1.774004 | X65: =K65*T65*'Molecular Weight'!$B$5/'Molecular Weight'!$D$5 -> 0.095426845 | Y65: =L65*T65*'Molecular Weight'!$B$6/'Molecular Weight'!$D$6 -> 0.24473544 | Z65: =M65*T65*'Molecular Weight'!$B$8/'Molecular Weight'!$D$8 -> 0.010698144 | AA65: =N65*T65*'Molecular Weight'!$B$9/'Molecular Weight'!$D$9 -> 2.4962756 | AB65: =O65*T65*'Molecular Weight'!$B$10/'Molecular Weight'!$D$10 -> 0.32704566 | AC65: =P65*T65*'Molecular Weight'!$B$11/'Molecular Weight'!$D$11 -> 0.017686786 | AD65: =Q65*T65*'Molecular Weight'!$B$12/'Molecular Weight'!$D$12 -> 0.0026855144 | AE65: =SUM(U65:AD65) -> 8.0220144 | AF65: =IF(IF(2*12*(1-8/AE65)<0,0,2*12*(1-8/AE65))<Y65,IF(2*12*(1-8/AE65)<0,0,2*12*(1-8/AE65)),Y65) -> 0.065861835 | AG65: =AF65/Y65 -> 0.26911441 | AH65: =Y65-AF65 -> 0.17887361 | AI65: =SUM(U65,V65) -> 3.0534564 | AJ65: =SUM(AA65,AB65,Z65,Y65) -> 3.0787548
A66: Ardia et al. (2012) | B66: 10.1016/j.epsl.2012.05.038 | C66: M473 | D66: 8 | E66: 1450 | F66: Peridotite | G66: Peridotitic | H66: 42.71 | I66: 0.18 | J66: 21.95 | K66: 1.75 | L66: 5.93 | M66: 0.16 | N66: 22.24 | O66: 3.9 | P66: 0.07 | Q66: 0.03 | R66: =SUM(H66:Q66) -> 98.92 | S66: 12 | T66: =S66/(H66*'Molecular Weight'!$C$2/'Molecular Weight'!$D$2+I66*'Molecular Weight'!$C$3/'Molecular Weight'!$D$3+J66*'Molecular Weight'!$C$4/'Molecular Weight'!$D$4+K66*'Molecular Weight'!$C$5/'Molecular Weight'!$D$5+L66*'Molecular Weight'!$C$6/'Molecular Weight'!$D$6+M66*'Molecular Weight'!$C$8/'Molecular Weight'!$D$8+N66*'Molecular Weight'!$C$9/'Molecular Weight'!$D$9+O66*'Molecular Weight'!$C$10/'Molecular Weight'!$D$10+P66*'Molecular Weight'!$C$11/'Molecular Weight'!$D$11+Q66*'Molecular Weight'!$C$12/'Molecular Weight'!$D$12) -> 4.2639192 | U66: =H66*T66*'Molecular Weight'!$B$2/'Molecular Weight'!$D$2 -> 3.0311583 | V66: =I66*T66*'Molecular Weight'!$B$3/'Molecular Weight'!$D$3 -> 0.0096058255 | W66: =T66*J66*'Molecular Weight'!$B$4/'Molecular Weight'!$D$4 -> 1.8358773 | X66: =K66*T66*'Molecular Weight'!$B$5/'Molecular Weight'!$D$5 -> 0.09818881 | Y66: =L66*T66*'Molecular Weight'!$B$6/'Molecular Weight'!$D$6 -> 0.35196326 | Z66: =M66*T66*'Molecular Weight'!$B$8/'Molecular Weight'!$D$8 -> 0.009616959 | AA66: =N66*T66*'Molecular Weight'!$B$9/'Molecular Weight'!$D$9 -> 2.3530909 | AB66: =O66*T66*'Molecular Weight'!$B$10/'Molecular Weight'!$D$10 -> 0.2965279 | AC66: =P66*T66*'Molecular Weight'!$B$11/'Molecular Weight'!$D$11 -> 0.0096313115 | AD66: =Q66*T66*'Molecular Weight'!$B$12/'Molecular Weight'!$D$12 -> 0.0027158721 | AE66: =SUM(U66:AD66) -> 7.9983764 | AF66: =IF(IF(2*12*(1-8/AE66)<0,0,2*12*(1-8/AE66))<Y66,IF(2*12*(1-8/AE66)<0,0,2*12*(1-8/AE66)),Y66) -> 0 | AG66: =AF66/Y66 -> 0 | AH66: =Y66-AF66 -> 0.35196326 | AI66: =SUM(U66,V66) -> 3.0407641 | AJ66: =SUM(AA66,AB66,Z66,Y66) -> 3.011199
A67: Ardia et al. (2012) | B67: 10.1016/j.epsl.2012.05.038 | C67: M442 | D67: 6 | E67: 1400 | F67: Peridotite | G67: Peridotitic | H67: 43.8 | I67: 0.17 | J67: 23.01 | K67: 1.75 | L67: 5.11 | M67: 0.22 | N67: 22.38 | O67: 5.07 | P67: 0.1 | Q67: 0.1 | R67: =SUM(H67:Q67) -> 101.71 | S67: 12 | T67: =S67/(H67*'Molecular Weight'!$C$2/'Molecular Weight'!$D$2+I67*'Molecular Weight'!$C$3/'Molecular Weight'!$D$3+J67*'Molecular Weight'!$C$4/'Molecular Weight'!$D$4+K67*'Molecular Weight'!$C$5/'Molecular Weight'!$D$5+L67*'Molecular Weight'!$C$6/'Molecular Weight'!$D$6+M67*'Molecular Weight'!$C$8/'Molecular Weight'!$D$8+N67*'Molecular Weight'!$C$9/'Molecular Weight'!$D$9+O67*'Molecular Weight'!$C$10/'Molecular Weight'!$D$10+P67*'Molecular Weight'!$C$11/'Molecular Weight'!$D$11+Q67*'Molecular Weight'!$C$12/'Molecular Weight'!$D$12) -> 4.1428864 | U67: =H67*T67*'Molecular Weight'!$B$2/'Molecular Weight'!$D$2 -> 3.0202801 | V67: =I67*T67*'Molecular Weight'!$B$3/'Molecular Weight'!$D$3 -> 0.008814652 | W67: =T67*J67*'Molecular Weight'!$B$4/'Molecular Weight'!$D$4 -> 1.8699062 | X67: =K67*T67*'Molecular Weight'!$B$5/'Molecular Weight'!$D$5 -> 0.095401688 | Y67: =L67*T67*'Molecular Weight'!$B$6/'Molecular Weight'!$D$6 -> 0.29468471 | Z67: =M67*T67*'Molecular Weight'!$B$8/'Molecular Weight'!$D$8 -> 0.01284797 | AA67: =N67*T67*'Molecular Weight'!$B$9/'Molecular Weight'!$D$9 -> 2.3006898 | AB67: =O67*T67*'Molecular Weight'!$B$10/'Molecular Weight'!$D$10 -> 0.37454412 | AC67: =P67*T67*'Molecular Weight'!$B$11/'Molecular Weight'!$D$11 -> 0.013368462 | AD67: =Q67*T67*'Molecular Weight'!$B$12/'Molecular Weight'!$D$12 -> 0.0087959372 | AE67: =SUM(U67:AD67) -> 7.9993336 | AF67: =IF(IF(2*12*(1-8/AE67)<0,0,2*12*(1-8/AE67))<Y67,IF(2*12*(1-8/AE67)<0,0,2*12*(1-8/AE67)),Y67) -> 0 | AG67: =AF67/Y67 -> 0 | AH67: =Y67-AF67 -> 0.29468471 | AI67: =SUM(U67,V67) -> 3.0290947 | AJ67: =SUM(AA67,AB67,Z67,Y67) -> 2.9827666
